test_p1 (__main__.Test.test_p1) ... ok
test_p2 (__main__.Test.test_p2) ... ok
test_p3 (__main__.Test.test_p3) ... ERROR
test_p4 (__main__.Test.test_p4) ... ERROR
test_p5 (__main__.Test.test_p5) ... ok
test_p6 (__main__.Test.test_p6) ... ERROR

======================================================================
ERROR: test_p3 (__main__.Test.test_p3)
----------------------------------------------------------------------
Traceback (most recent call last):
  File "c:\Users\wikaw\Desktop\pp1\05-Test1\mock\check.py", line 27, in test_p3
    import mock.p3 as p3
ModuleNotFoundError: No module named 'mock'

======================================================================
ERROR: test_p4 (__main__.Test.test_p4)
----------------------------------------------------------------------
Traceback (most recent call last):
  File "c:\Users\wikaw\Desktop\pp1\05-Test1\mock\check.py", line 32, in test_p4
    import mock.p4 as p4
ModuleNotFoundError: No module named 'mock'

======================================================================
ERROR: test_p6 (__main__.Test.test_p6)
----------------------------------------------------------------------
Traceback (most recent call last):
  File "c:\Users\wikaw\Desktop\pp1\05-Test1\mock\check.py", line 43, in test_p6
    import p6
ModuleNotFoundError: No module named 'p6'

----------------------------------------------------------------------
Ran 6 tests in 0.002s

FAILED (errors=3)
